Workbook

Sheet ReadMe
A1: Connectomics Budget Template — Quick guide
A3: Explainer Loom here.

Sheet Comparison
A1: Cross-method comparison (Central values)
B2: With current proofreading | F2: With 1,000x improved proofreading
A3: ='Connectome with proofreading'!A52 -> Human proofreading hours per neuron | B3: 5 | F3: 0.005
A4: ='Connectome with proofreading'!A53 -> Hourly rate of proof-reader | B4: 50 | F4: 50
A5: ='Connectome with proofreading'!A54 -> Proofreading hours per day | B5: 6 | F5: 6
A6: ='Connectome with proofreading'!A55 -> Number of proofreaders | B6: 25000 | F6: 1000
B7: With current proofreading | F7: With 1,000x improved proofreading
A8: Paradigm | B8: Electron Microscopy (Wellcome) 2023 | C8: Electron Microscopy 2025 | D8: Expansion Microscopy 2025 | E8: ="ExM "&'Specification Imaging Modalitie'!G7&" Molecular Annotations"&CHAR(10)&"2025" -> ExM 800 Molecular Annotations 2025 | F8: Electron Microscopy (Wellcome) 2023 | G8: Electron Microscopy 2025 | H8: Expansion Microscopy 2025 | I8: ="ExM "&'Specification Imaging Modalitie'!G7&" Molecular Annotations"&CHAR(10)&"2025" -> ExM 800 Molecular Annotations 2025
A9: ='Connectome with proofreading'!A147 -> Total duration | B9: ='Connectome with proofreading'!I147 -> 5 | C9: ='Connectome with proofreading'!F147 -> 5 | D9: ='Connectome with proofreading'!G147 -> 5 | E9: ='Connectome with proofreading'!H147 -> 5 | F9: ='Connectome without proofreading'!I147 -> 5 | G9: ='Connectome without proofreading'!F147 -> 5 | H9: ='Connectome without proofreading'!G147 -> 5 | I9: ='Connectome without proofreading'!H147 -> 5
A10: ='Connectome with proofreading'!A148 -> Total connectomes | B10: ='Connectome with proofreading'!I148 -> 1 | C10: ='Connectome with proofreading'!F148 -> 1 | D10: ='Connectome with proofreading'!G148 -> 1 | E10: ='Connectome with proofreading'!H148 -> 1 | F10: ='Connectome without proofreading'!I148 -> 1 | G10: ='Connectome without proofreading'!F148 -> 18 | H10: ='Connectome without proofreading'!G148 -> 31 | I10: ='Connectome without proofreading'!H148 -> 2
A11: ='Connectome with proofreading'!A150 -> Timelines
A12: ='Connectome with proofreading'!A151 -> Imaging years | B12: ='Connectome with proofreading'!I151 -> 6.4471145 | C12: ='Connectome with proofreading'!F151 -> 0.24988464 | D12: ='Connectome with proofreading'!G151 -> 0.048967606 | E12: ='Connectome with proofreading'!H151 -> 2.4026106 | F12: ='Connectome without proofreading'!I151 -> 7.0172501 | G12: ='Connectome without proofreading'!F151 -> 0.27076352 | H12: ='Connectome without proofreading'!G151 -> 0.049754778 | I12: ='Connectome without proofreading'!H151 -> 2.638762
A13: ='Connectome with proofreading'!A152 -> Processing years | B13: ='Connectome with proofreading'!I152 -> 0.20429502 | C13: ='Connectome with proofreading'!F152 -> 0.061125308 | D13: ='Connectome with proofreading'!G152 -> 0.024052312 | E13: ='Connectome with proofreading'!H152 -> 0.024037662 | F13: ='Connectome without proofreading'!I152 -> 0.20429502 | G13: ='Connectome without proofreading'!F152 -> 0.061125308 | H13: ='Connectome without proofreading'!G152 -> 0.024052312 | I13: ='Connectome without proofreading'!H152 -> 0.024037662
A14: ='Connectome with proofreading'!A153 -> Proofreading years | B14: ='Connectome with proofreading'!I153 -> 6.3926941 | C14: ='Connectome with proofreading'!F153 -> 6.3926941 | D14: ='Connectome with proofreading'!G153 -> 6.3926941 | E14: ='Connectome with proofreading'!H153 -> 6.3926941 | F14: ='Connectome without proofreading'!I153 -> 0.15981735 | G14: ='Connectome without proofreading'!F153 -> 0.15981735 | H14: ='Connectome without proofreading'!G153 -> 0.15981735 | I14: ='Connectome without proofreading'!H153 -> 0.15981735
A15: ='Connectome with proofreading'!A154 -> Buffer years | B15: ='Connectome with proofreading'!I154 -> 2.6088207 | C15: ='Connectome with proofreading'!F154 -> 1.3407408 | D15: ='Connectome with proofreading'!G154 -> 1.2931428 | E15: ='Connectome with proofreading'!H154 -> 1.7638685 | F15: ='Connectome without proofreading'!I154 -> 1.4762725 | G15: ='Connectome without proofreading'!F154 -> 0.098341236 | H15: ='Connectome without proofreading'!G154 -> 0.046724888 | I15: ='Connectome without proofreading'!H154 -> 0.56452341
A16: ='Connectome with proofreading'!A155 -> Total years First connectome | B16: ='Connectome with proofreading'!I155 -> 15.652924 | C16: ='Connectome with proofreading'!F155 -> 8.0444448 | D16: ='Connectome with proofreading'!G155 -> 7.7588568 | E16: ='Connectome with proofreading'!H155 -> 10.583211 | F16: ='Connectome without proofreading'!I155 -> 8.857635 | G16: ='Connectome without proofreading'!F155 -> 0.59004741 | H16: ='Connectome without proofreading'!G155 -> 0.28034933 | I16: ='Connectome without proofreading'!H155 -> 3.3871405
A17: ='Connectome with proofreading'!A156 -> Time to marginal | B17: ='Connectome with proofreading'!I156 -> 6.4471145 | C17: ='Connectome with proofreading'!F156 -> 6.3926941 | D17: ='Connectome with proofreading'!G156 -> 6.3926941 | E17: ='Connectome with proofreading'!H156 -> 6.3926941 | F17: ='Connectome without proofreading'!I156 -> 7.0172501 | G17: ='Connectome without proofreading'!F156 -> 0.27076352 | H17: ='Connectome without proofreading'!G156 -> 0.15981735 | I17: ='Connectome without proofreading'!H156 -> 2.638762
A18: ='Connectome with proofreading'!A157 -> Average Connectome
A19: ='Connectome with proofreading'!A158 -> Imaging $ | B19: ='Connectome with proofreading'!I158 -> 1.8801586e+08 | C19: ='Connectome with proofreading'!F158 -> 1.0917373e+08 | D19: ='Connectome with proofreading'!G158 -> 56616974 | E19: ='Connectome with proofreading'!H158 -> 66595181 | F19: ='Connectome without proofreading'!I158 -> 1.9080953e+08 | G19: ='Connectome without proofreading'!F158 -> 57458954 | H19: ='Connectome without proofreading'!G158 -> 3394237.2 | I19: ='Connectome without proofreading'!H158 -> 40016172
A20: ='Connectome with proofreading'!A159 -> Storage $ | B20: ='Connectome with proofreading'!I159 -> 185781250 | C20: ='Connectome with proofreading'!F159 -> 55046296 | D20: ='Connectome with proofreading'!G159 -> 30438400 | E20: ='Connectome with proofreading'!H159 -> 30438400 | F20: ='Connectome without proofreading'!I159 -> 204359375 | G20: ='Connectome without proofreading'!F159 -> 4777983.5 | H20: ='Connectome without proofreading'!G159 -> 1881269.7 | I20: ='Connectome without proofreading'!H159 -> 17155072
A21: ='Connectome with proofreading'!A160 -> Processing $ | B21: ='Connectome with proofreading'!I160 -> 5579248.8 | C21: ='Connectome with proofreading'!F160 -> 2613629.5 | D21: ='Connectome with proofreading'!G160 -> 2421138.6 | E21: ='Connectome with proofreading'!H160 -> 2421096.6 | F21: ='Connectome without proofreading'!I160 -> 5895064.8 | G21: ='Connectome without proofreading'!F160 -> 743994.77 | H21: ='Connectome without proofreading'!G160 -> 485659.8 | I21: ='Connectome without proofreading'!H160 -> 1421097.4
A22: ='Connectome with proofreading'!A161 -> Proofreading $ | B22: ='Connectome with proofreading'!I161 -> 17500000000 | C22: ='Connectome with proofreading'!F161 -> 5185185185 | D22: ='Connectome with proofreading'!G161 -> 2867200000 | E22: ='Connectome with proofreading'!H161 -> 2867200000 | F22: ='Connectome without proofreading'!I161 -> 19250000 | G22: ='Connectome without proofreading'!F161 -> 5703703.7 | H22: ='Connectome without proofreading'!G161 -> 3153920 | I22: ='Connectome without proofreading'!H161 -> 3153920
A23: ='Connectome with proofreading'!A162 -> Personnel $ | B23: ='Connectome with proofreading'!I162 -> 26250000 | C23: ='Connectome with proofreading'!F162 -> 26250000 | D23: ='Connectome with proofreading'!G162 -> 26250000 | E23: ='Connectome with proofreading'!H162 -> 26250000 | F23: ='Connectome without proofreading'!I162 -> 26250000 | G23: ='Connectome without proofreading'!F162 -> 1458333.3 | H23: ='Connectome without proofreading'!G162 -> 846774.19 | I23: ='Connectome without proofreading'!H162 -> 13125000
A24: ='Connectome with proofreading'!A163 -> Buffer $ | B24: ='Connectome with proofreading'!I163 -> 3581125272 | C24: ='Connectome with proofreading'!F163 -> 1075653768 | D24: ='Connectome with proofreading'!G163 -> 5.965853e+08 | E24: ='Connectome with proofreading'!H163 -> 5.9858094e+08 | F24: ='Connectome without proofreading'!I163 -> 89312793 | G24: ='Connectome without proofreading'!F163 -> 5005058.9 | H24: ='Connectome without proofreading'!G163 -> 955145.24 | I24: ='Connectome without proofreading'!H163 -> 12720945
A25: ='Connectome with proofreading'!A164 -> Total $ | B25: ='Connectome with proofreading'!I164 -> 21486751632 | C25: ='Connectome with proofreading'!F164 -> 6453922610 | D25: ='Connectome with proofreading'!G164 -> 3579511815 | E25: ='Connectome with proofreading'!H164 -> 3591485613 | F25: ='Connectome without proofreading'!I164 -> 5.3587676e+08 | G25: ='Connectome without proofreading'!F164 -> 75148028 | H25: ='Connectome without proofreading'!G164 -> 10717006 | I25: ='Connectome without proofreading'!H164 -> 87592207
A26: ='Connectome with proofreading'!A165 -> Cost per neuron | B26: ='Connectome with proofreading'!I165 -> 306.95359 | C26: ='Connectome with proofreading'!F165 -> 92.198894 | D26: ='Connectome with proofreading'!G165 -> 51.135883 | E26: ='Connectome with proofreading'!H165 -> 51.306937 | F26: ='Connectome without proofreading'!I165 -> 7.6553823 | G26: ='Connectome without proofreading'!F165 -> 1.0735433 | H26: ='Connectome without proofreading'!G165 -> 0.15310009 | I26: ='Connectome without proofreading'!H165 -> 1.2513172
A27: ='Connectome with proofreading'!A166 -> First Connectome | B27: ='Connectome with proofreading'!I166 | C27: ='Connectome with proofreading'!F166 | D27: ='Connectome with proofreading'!G166 | E27: ='Connectome with proofreading'!H166 | F27: ='Connectome without proofreading'!I166 | G27: ='Connectome without proofreading'!F166 | H27: ='Connectome without proofreading'!G166 | I27: ='Connectome without proofreading'!H166
A28: ='Connectome with proofreading'!A167 -> Imaging $ | B28: ='Connectome with proofreading'!I167 -> 1.8801586e+08 | C28: ='Connectome with proofreading'!F167 -> 1.0917373e+08 | D28: ='Connectome with proofreading'!G167 -> 56616974 | E28: ='Connectome with proofreading'!H167 -> 66595181 | F28: ='Connectome without proofreading'!I167 -> 1.9080953e+08 | G28: ='Connectome without proofreading'!F167 -> 1.094034e+08 | H28: ='Connectome without proofreading'!G167 -> 56620044 | I28: ='Connectome without proofreading'!H167 -> 67516172
A29: ='Connectome with proofreading'!A168 -> Storage $ | B29: ='Connectome with proofreading'!I168 -> 185781250 | C29: ='Connectome with proofreading'!F168 -> 55046296 | D29: ='Connectome with proofreading'!G168 -> 30438400 | E29: ='Connectome with proofreading'!H168 -> 30438400 | F29: ='Connectome without proofreading'!I168 -> 204359375 | G29: ='Connectome without proofreading'!F168 -> 60550926 | H29: ='Connectome without proofreading'!G168 -> 33482240 | I29: ='Connectome without proofreading'!H168 -> 33482240
A30: ='Connectome with proofreading'!A169 -> Processing $ | B30: ='Connectome with proofreading'!I169 -> 5579248.8 | C30: ='Connectome with proofreading'!F169 -> 2613629.5 | D30: ='Connectome with proofreading'!G169 -> 2421138.6 | E30: ='Connectome with proofreading'!H169 -> 2421096.6 | F30: ='Connectome without proofreading'!I169 -> 5895064.8 | G30: ='Connectome without proofreading'!F169 -> 2632883.7 | H30: ='Connectome without proofreading'!G169 -> 2421143.7 | I30: ='Connectome without proofreading'!H169 -> 2421097.4
... A44: ='Connectome with proofreading'!A183 -> Cost per neuron | B44: ='Connectome with proofreading'!I183 -> 265.01158 | C44: ='Connectome with proofreading'!F183 -> 79.013755 | D44: ='Connectome with proofreading'!G183 -> 43.443611 | E44: ='Connectome with proofreading'!H183 -> 43.593284 | F44: ='Connectome without proofreading'!I183 -> 2.8538657 | G44: ='Connectome without proofreading'!F183 -> 0.95543312 | H44: ='Connectome without proofreading'!G183 -> 0.10304678 | I44: ='Connectome without proofreading'!H183 -> 0.4506614
A45: Cost per mm^3 | C45: =C43/500 -> 11061926 | D45: =D43/500 -> 6082105.6 | E45: =E43/500 -> 6103059.7 | F45: =F43/500 -> 399541.2 | G45: =G43/500 -> 133760.64 | H45: =H43/500 -> 14426.55 | I45: =I43/500 -> 63092.596
A46: ='Connectome with proofreading'!A185
A48: Total Capital | B48: =B25*B10 -> 21486751632 | C48: =C25*C10 -> 6453922610 | D48: =D25*D10 -> 3579511815 | E48: =E25*E10 -> 3591485613 | F48: =F25*F10 -> 5.3587676e+08 | G48: =G25*G10 -> 1352664513 | H48: =H25*H10 -> 3.3222719e+08 | I48: =I25*I10 -> 1.7518441e+08

Sheet Shared Specifications
A1: Item | B1: Definition | C1: Units | D1: Sources and Comments | E1: Standardized Variables Proofreading Paradigm
A2: Shared General Specifications
A3: Specifications Organism & Scope
A4: Quality target | C4: - | E4: Synaptic Resultion, staining only, no antibodies
A5: Organism / Region | C5: - | E5: Complete Mousebrain
A6: Risk buffer policy first connectome | B6: Budget and schedule contingency fraction | C6: fraction | D6: Standard range of risk buffers | E6: 0.2
A7: Risk Buffer for marginal connectomes | B7: Budget and schedule contingency fraction | C7: fraction | D7: Standard range of risk buffers | E7: 0.05
A8: Volume (biological) | B8: Physical brain volume to be mapped | C8: mm^3 | D8: Differently sized brains | E8: 500
A9: Number of neurons | B9: Number of neurons in the given volume | C9: count | D9: based on State of Brain Emulation report | E9: 70000000
A10: Specifications Counts
A11: Years until start | B11: Years from now when initial purchases are made | C11: years | D11: assumptions | E11: 0
A12: Planned Project duration (years) | B12: Time span for overall project | C12: years | D12: assumptions | E12: 5
A13: Dollars available for Microscopes | B13: Upfront investment in microscopes | C13: $ | D13: assumptions | E13: 50000000
A14: Max parallel GPUs available | B14: Number of GPUs dedicated during processing | C14: count | D14: assumptions | E14: 1000
A15: Facility per year | B15: Cleanroom, isolation, HVAC, racks across whole project lifespan | C15: $ | D15: assumptions | E15: 2000000
A16: Average Staff salary | B16: Average salary with all overheads across the project | C16: $/year | D16: assumptions | E16: 150000
A17: Project management staff | B17: Staff members for management of project oversight | C17: FTE count | D17: assumptions | E17: 10
A18: Technical Staff beyond sample and microscope operations | B18: Sample prep and microscope operations are included in calculations already. This is staff beyond that | C18: FTE count | D18: assumptions | E18: 15
A19: Misc. Staff | B19: Operations, Assitants, PR, etc | C19: FTE count | D19: assumptions | E19: 10
A20: Other costs per connectome | B20: Shipping, permits, biosafety, IP, pubs | C20: $/project | D20: misc. costs | E20: 250000
A21: Facility costs | B21: Costs of facility over whole project duration | C21: $ | D21: calculation | E21: =E15*E12 -> 10000000
A22: Total capital base | B22: Scopes + facility + core SW + initial training | C22: $ | D22: calculation | E22: =E13+E15*E12/2 -> 55000000
A23: Data science one off developments | B23: Pipelines, data mgmt, viewers, model training | C23: $ | D23: assumptions Example: Liccon reported "Training ran up to 30 days on 32 NVIDIA V100 GPUs with about 8.8 million steps (batch size 128), and they also trained a semantic classifier on 16 V100s for ~38 h." which is probably 10k. Let's assume we need 10x that for different models | E23: 2000000
A24: Specifications Hardware
A25: Peak FLOPs/s for GPU | B25: Maximum FP 16 FLOP/s for GPU | C25: TFLOPs/s | D25: H100 FP 16 with 1,979 TFLOPs: https://www.nvidia.com/en-us/data-center/h100/ So far architectures in connectomics use FP32, but at scale FP16 seems more reasonable. | E25: 1979
A26: Percentage continuous GPU usage | B26: Continuous GPU usage across time | C26: fraction | D26: estimate | E26: 0.8
A27: $ / h for GPU usage | B27: Costs for access to 1h of GPU | C27: $ / hour | D27: at scale pricing for GPUs | E27: 2
A28: Cost drop compute per year | B28: Cost drop compute per year | C28: fraction | D28: assumption from past trends | E28: 0.1
A29: cost drop storage per year | B29: cost drop storage per year | C29: fraction | D29: assumption from past trends | E29: 0.05
A30: Active storage costs PB-month | B30: Storage system for working files | C30: $ / month | D30: Taking on-premise pricing See https://aws.amazon.com/s3/pricing/ accessed 2025-09-04 Frequent Access Tier, First 50 TB / Month $0.023 per GB Frequent Access Tier, Next 450 TB / Month $0.022 per GB Frequent Access Tier, Over 500 TB / Month $0.021 per GB Infrequent Access Tier, All Storage / Month $0.0125 per GB Archive Instant Access Tier, All Storage / Month $0.004 per GB For on-prem assumption is that standard is 8x cheaper, archive 2x cheaper | E30: =21000/8 -> 2625
A31: Archive storage costs PB-month | B31: Storage system for backup files | C31: $ / month | D31: see above | E31: =4000/2 -> 2000
A32: Bytes per voxel | D32: Assuming 8-bits per voxel at 1 byte | E32: 1
A33: Lossless compression ratio | B33: Raw to lossless | C33: × | D33: as per Wellcome Trust Report; assumed to happen in parallel to image acquisition | E33: 1.5
A34: Lossy compression ratio | B34: Raw to lossy | C34: × | D34: estimate; 120x compression demonstrated for EM; assumed to happen in parallel to image acquisition | E34: 120
A35: Structure Label overheads | B35: labels + meshes + skeletons + graphs + annotations overhead | C35: % | D35: estimate for image overlays for labels | E35: 0.05
A36: Replicas First (active) | B36: Hot copies lossless online of first connectome | C36: count | D36: assumptions | E36: 3
A37: Replicas First (archive) | B37: Cold copies retained first connectome | C37: count | D37: assumptions | E37: 2
A38: Replicas Marginal (active) | B38: Hot copies lossless online of marginal connectomes | C38: count | D38: assumptions | E38: 1
A39: Replicas Marginal (archive) | B39: Cold copies retained of marginal connectomes | C39: count | D39: assumptions | E39: 0
A40: Active retention (years) | B40: How long active copies are kept | C40: yr | D40: assumptions | E40: 5
...

Sheet Specification Imaging Modalitie
A1: Item | B1: Definition | C1: Units | D1: Sources and Comments | E1: EM | F1: ExM | G1: ExM Molecular Annotation | H1: Wellcome EM Replication
A2: Definitions from | E2: https://www.nature.com/articles/s41467-024-50846-4 | F2: https://pmc.ncbi.nlm.nih.gov/articles/PMC12157702/ | G2: https://pmc.ncbi.nlm.nih.gov/articles/PMC12157702/
A3: Microscope capital cost | B3: Acquisition price per scope | C3: $/scope | E3: 500000 | F3: 500000 | G3: 500000 | H3: 5000000
A4: Microscope depreciation horizon | B4: Straight-line depreciation years | C4: yr | E4: 10 | F4: 5 | G4: 5 | H4: 10
A5: Sustained Imaging Rate | B5: Sustained Imaging rate at given resolution per Microscope, i.e. voxels/second/scope | C5: Mvox/s | D5: This seems to be quite similar to EMs out there, both in terms of bursts going into the GHz and continuous around 100s of MHz | E5: 225 | F5: 1100 | G5: 1100 | H5: 250
A6: Parallel Channels per round | B6: simultaneous channel readouts (not sequential during one round) | D6: Just staining, no antibodies | E6: 1 | F6: 3 | G6: 8 | H6: 1
A7: Total Channels | B7: Imaging channels per voxel | C7: count | D7: Just staining, no antibodies | E7: 1 | F7: 1 | G7: 800 | H7: 1
A8: Scope annual service | B8: Electricity, licenses, Maintenance or spares | C8: $/scope/year | E8: 50000 | F8: 15000 | G8: 15000 | H8: 250000
A9: Salary Microscope technician | B9: Total Salary, incl benefits etc. for microscopist (incl. wetlab work) | C9: $/year | E9: 120000 | F9: 120000 | G9: 120000 | H9: 120000
A10: Microscope technician ratio | B10: Number of Microscopes maintained by one technician | C10: count | E10: 2 | F10: 5 | G10: 5 | H10: 0.5
A11: Microscope uptime | B11: Fraction of calendar time producing good data, incl Time lost to swaps/alignment beyond uptime | C11: fraction | D11: I assume you can rotate samples in such a way that you keep uptime relatively high still? | E11: 1 | F11: 1 | G11: 1 | H11: 1
A12: Reacquisition rate | B12: Expected fraction of volume to re-image | C12: fraction | D12: for simplicity none. Buffer budget at the end accounts for errors | E12: 0 | F12: 0 | G12: 0 | H12: 0
A13: Sample yield | B13: Fraction of samples that pass QC | C13: fraction | D13: for simplicity full. Buffer at the end accounts for errors | E13: 1 | F13: 1 | G13: 1 | H13: 1
A14: Expansion factor | B14: Linear expansion factor E; effective volume scales as E^3 | C14: × | D14: 26.666 expands 400nm resolution to 15nm | E14: 1 | F14: 16 | G14: 16 | H14: 1
A15: Consumables per original mm^3 | B15: Sample prep, expanding, staining, ... per imaged tissue volume | C15: $/mm^3 | D15: For EM paper states $4 Per grid tape film per slot. with about 25k slots per mm, we are at 100-200k at scale. Knives are neglidgible Estimate with 2$ per mm^3 original tissue based on LICONN supplement. | E15: =100000 -> 100000 | F15: 2 | G15: 2 | H15: 200000
A16: Antibody costs per original mm^3 | C16: $/mm^3 | D16: 2$ per mm^3 original tissue; estimate | E16: 2 | F16: 2 | G16: 2 | H16: 2
A17: Human Labor costs per original mm^3 | C17: $/mm^3 | D17: 120k salary, working 210d per year, one week of work per mm^3 | E17: 2850 | F17: 2850 | G17: 2850 | H17: 2850
A18: Initial Preparation days | B18: From tissue to ready-to-image | C18: days | D18: initial preparation of tissue | E18: 15 | F18: 15 | G18: 15 | H18: 15
A19: Voxel size X | B19: Acquisition resolution X | C19: nm | E19: 15 | F19: 250 | G19: 250 | H19: 10
A20: Voxel size Y | B20: Acquisition resolution Y | C20: nm | E20: 15 | F20: 250 | G20: 250 | H20: 10
A21: Voxel size Z | B21: Acquisition resolution Z | C21: nm | E21: 15 | F21: 400 | G21: 400 | H21: 10
A22: Sample depth | B22: Layers of Z in one sample, so no alignment necessary later | C22: count | D22: a sample with 10,000 slices can be imaged at once. Unlike serial EM, ExM does not require cutting the tissue into thousands of thin sections. The sample remains intact (embedded in a hydrogel), and is typically imaged as a continuous volume (e.g. via a light-sheet Z-stack) rather than separate physical slices. This eliminates section-to-section alignment altogether. Distortions due to cutting or mounting are absent – the only geometric distortions might come from the expansion process, but these are mostly uniform isotropic stretching. | E22: 1 | F22: 10000 | G22: 10000 | H22: 1
A23: Image size pixels x | C23: px | D23: from LICONN paper. Could go up to ExaSpim with 14,192 x 10,640 pixels | E23: 6000 | F23: 2048 | G23: 5000 | H23: 5000
A24: Image size pixels y | C24: px | E24: 6000 | F24: 2048 | G24: 5000 | H24: 5000
A25: Tile overlap | E25: 0.1 | F25: 0.1 | G25: 0.1 | H25: 0.1

Sheet Connectome with proofreading
A1: Connectome with Proofreading
A2: Item | B2: Definition | C2: Units | D2: Sources and Comments | E2: Standardized Variables Proofreading Paradigm | F2: EM | G2: ExM | H2: ExM Molecular Annotation | I2: Wellcome EM Replication
A3: Shared General Specifications
A4: Specifications Organism & Scope
A5: Quality target | B5: Synaptic Resultion, staining only, no antibodies | C5: -
A6: Organism / Region | B6: ='Shared Specifications'!E5 -> Complete Mousebrain | C6: ='Shared Specifications'!C5 -> - | D6: ='Shared Specifications'!D5 | E6: ='Shared Specifications'!E5 -> Complete Mousebrain | F6: =$E6 -> Complete Mousebrain | G6: =$E6 -> Complete Mousebrain | H6: =$E6 -> Complete Mousebrain | I6: =$E6 -> Complete Mousebrain
A7: Risk buffer policy first connectome | B7: ='Shared Specifications'!B6 -> Budget and schedule contingency fraction | C7: ='Shared Specifications'!C6 -> fraction | D7: ='Shared Specifications'!D6 -> Standard range of risk buffers | E7: ='Shared Specifications'!E6 -> 0.2 | F7: =$E7 -> 0.2 | G7: =$E7 -> 0.2 | H7: =$E7 -> 0.2 | I7: =$E7 -> 0.2
A8: Risk Buffer for marginal connectomes | B8: ='Shared Specifications'!B7 -> Budget and schedule contingency fraction | C8: ='Shared Specifications'!C7 -> fraction | D8: ='Shared Specifications'!D7 -> Standard range of risk buffers | E8: ='Shared Specifications'!E7 -> 0.05 | F8: =$E8 -> 0.05 | G8: =$E8 -> 0.05 | H8: =$E8 -> 0.05 | I8: =$E8 -> 0.05
A9: Volume (biological) | B9: ='Shared Specifications'!B8 -> Physical brain volume to be mapped | C9: ='Shared Specifications'!C8 -> mm^3 | D9: ='Shared Specifications'!D8 -> Differently sized brains | E9: ='Shared Specifications'!E8 -> 500 | F9: =$E9 -> 500 | G9: =$E9 -> 500 | H9: =$E9 -> 500 | I9: =$E9 -> 500
A10: Number of neurons | B10: ='Shared Specifications'!B9 -> Number of neurons in the given volume | C10: ='Shared Specifications'!C9 -> count | D10: ='Shared Specifications'!D9 -> based on State of Brain Emulation report | E10: ='Shared Specifications'!E9 -> 70000000 | F10: =$E10 -> 70000000 | G10: =$E10 -> 70000000 | H10: =$E10 -> 70000000 | I10: =$E10 -> 70000000
A11: Specifications Counts | B11: ='Shared Specifications'!B10 | C11: ='Shared Specifications'!C10 | D11: ='Shared Specifications'!D10 | E11: ='Shared Specifications'!E10 | F11: =$E11 | G11: =$E11 | H11: =$E11 | I11: =$E11
A12: Years until start | B12: ='Shared Specifications'!B11 -> Years from now when initial purchases are made | C12: ='Shared Specifications'!C11 -> years | D12: ='Shared Specifications'!D11 -> assumptions | E12: ='Shared Specifications'!E11 -> 0 | F12: =$E12 -> 0 | G12: =$E12 -> 0 | H12: =$E12 -> 0 | I12: =$E12 -> 0
A13: Planned Project duration (years) | B13: ='Shared Specifications'!B12 -> Time span for overall project | C13: ='Shared Specifications'!C12 -> years | D13: ='Shared Specifications'!D12 -> assumptions | E13: ='Shared Specifications'!E12 -> 5 | F13: =$E13 -> 5 | G13: =$E13 -> 5 | H13: =$E13 -> 5 | I13: =$E13 -> 5
A14: Dollars available for Microscopes | B14: ='Shared Specifications'!B13 -> Upfront investment in microscopes | C14: ='Shared Specifications'!C13 -> $ | D14: ='Shared Specifications'!D13 -> assumptions | E14: ='Shared Specifications'!E13 -> 50000000 | F14: =$E14 -> 50000000 | G14: =$E14 -> 50000000 | H14: =$E14 -> 50000000 | I14: =$E14 -> 50000000
A15: Max parallel GPUs available | B15: ='Shared Specifications'!B14 -> Number of GPUs dedicated during processing | C15: ='Shared Specifications'!C14 -> count | D15: ='Shared Specifications'!D14 -> assumptions | E15: ='Shared Specifications'!E14 -> 1000 | F15: =$E15 -> 1000 | G15: =$E15 -> 1000 | H15: =$E15 -> 1000 | I15: =$E15 -> 1000
A16: Facility per year | B16: ='Shared Specifications'!B15 -> Cleanroom, isolation, HVAC, racks across whole project lifespan | C16: ='Shared Specifications'!C15 -> $ | D16: ='Shared Specifications'!D15 -> assumptions | E16: ='Shared Specifications'!E15 -> 2000000 | F16: =$E16 -> 2000000 | G16: =$E16 -> 2000000 | H16: =$E16 -> 2000000 | I16: =$E16 -> 2000000
A17: Average Staff salary | B17: ='Shared Specifications'!B16 -> Average salary with all overheads across the project | C17: ='Shared Specifications'!C16 -> $/year | D17: ='Shared Specifications'!D16 -> assumptions | E17: ='Shared Specifications'!E16 -> 150000 | F17: =$E17 -> 150000 | G17: =$E17 -> 150000 | H17: =$E17 -> 150000 | I17: =$E17 -> 150000
A18: Project management staff | B18: ='Shared Specifications'!B17 -> Staff members for management of project oversight | C18: ='Shared Specifications'!C17 -> FTE count | D18: ='Shared Specifications'!D17 -> assumptions | E18: ='Shared Specifications'!E17 -> 10 | F18: =$E18 -> 10 | G18: =$E18 -> 10 | H18: =$E18 -> 10 | I18: =$E18 -> 10
... A49: Segmentation FLOP per voxel | B49: ='Shared Specifications'!B48 -> FP32-equivalent Floating point operations/voxel. | C49: ='Shared Specifications'!C48 -> TFLOP / voxel | D49: ='Shared Specifications'!D48 -> We are assuming 2M FLOP / voxel with LSDs. based on 1/100 of FFN that are 2.42×108 FLOPs/voxel https://www.nature.com/articles/s41592-022-01711-z and https://static-content.springer.com/esm/art%3A10.1038%2Fs41592-018-0049-4/MediaObjects/41592_2018_49_MOESM1_ESM.pdf#page=11 | E49: ='Shared Specifications'!E48 -> 2.4e-06 | F49: =$E49 -> 2.4e-06 | G49: =$E49 -> 2.4e-06 | H49: =$E49 -> 2.4e-06 | I49: =$E49 -> 2.4e-06
A51: Shared Proofreading Specifications
A52: Human proofreading hours per neuron | B52: Human proofreading time per neuron | C52: hours | D52: Flywire reports on average 20min per neuron. From personal communication with MICrONS authors we know that bigger mouse neurons can be way more complex and go up to 40h / neuron | E52: =Comparison!B3 -> 5 | F52: =$E52 -> 5 | G52: =$E52 -> 5 | H52: =$E52 -> 5 | I52: =$E52 -> 5
A53: Hourly rate of proof-reader | B53: Average Compensation for proofreading hour | C53: $/hour | D53: Outsourced salary in non-developped country | E53: =Comparison!B4 -> 50 | F53: =$E53 -> 50 | G53: =$E53 -> 50 | H53: =$E53 -> 50 | I53: =$E53 -> 50
A54: Proofreading hours per day | B54: average hours a proofreader works per day | C54: hours / day | D54: assumption | E54: =Comparison!B5 -> 6 | F54: =$E54 -> 6 | G54: =$E54 -> 6 | H54: =$E54 -> 6 | I54: =$E54 -> 6
A55: Number of proofreaders | B55: Number of people proofreading. | C55: count | D55: backchaining from Wellcome estimate and Targeting 5years with people working 6h / day for 210 days per year for a mouse | E55: =Comparison!B6 -> 25000 | F55: =$E55 -> 25000 | G55: =$E55 -> 25000 | H55: =$E55 -> 25000 | I55: =$E55 -> 25000
A57: Unique Specifications Microscope | F57: ='Specification Imaging Modalitie'!E2 -> https://www.nature.com/articles/s41467-024-50846-4
A58: Microscope capital cost | B58: Acquisition price per scope | C58: $/scope | F58: ='Specification Imaging Modalitie'!E3 -> 500000 | G58: ='Specification Imaging Modalitie'!F3 -> 500000 | H58: ='Specification Imaging Modalitie'!G3 -> 500000 | I58: 5000000
A59: Microscope depreciation horizon | B59: Straight-line depreciation years | C59: yr | F59: ='Specification Imaging Modalitie'!E4 -> 10 | G59: ='Specification Imaging Modalitie'!F4 -> 5 | H59: ='Specification Imaging Modalitie'!G4 -> 5 | I59: 10
A60: Sustained Imaging Rate | B60: Sustained Imaging rate at given resolution per Microscope, i.e. voxels/second/scope | C60: Mvox/s | D60: This seems to be quite similar to EMs out there, both in terms of bursts going into the GHz and continuous around 100s of MHz | F60: ='Specification Imaging Modalitie'!E5 -> 225 | G60: ='Specification Imaging Modalitie'!F5 -> 1100 | H60: ='Specification Imaging Modalitie'!G5 -> 1100 | I60: 250
A61: Parallel Channels per round | B61: simultaneous channel readouts (not sequential during one round) | D61: Just staining, no antibodies | F61: ='Specification Imaging Modalitie'!E6 -> 1 | G61: ='Specification Imaging Modalitie'!F6 -> 3 | H61: ='Specification Imaging Modalitie'!G6 -> 8 | I61: 1
A62: Total Channels | B62: Imaging channels per voxel | C62: count | D62: Just staining, no antibodies | F62: ='Specification Imaging Modalitie'!E7 -> 1 | G62: ='Specification Imaging Modalitie'!F7 -> 1 | H62: ='Specification Imaging Modalitie'!G7 -> 800 | I62: 1
A63: Scope annual service | B63: Electricity, licenses, Maintenance or spares | C63: $/scope/year | F63: ='Specification Imaging Modalitie'!E8 -> 50000 | G63: ='Specification Imaging Modalitie'!F8 -> 15000 | H63: ='Specification Imaging Modalitie'!G8 -> 15000 | I63: 250000
A64: Salary Microscope technician | B64: Total Salary, incl benefits etc. for microscopist (incl. wetlab work) | C64: $/year | F64: ='Specification Imaging Modalitie'!E9 -> 120000 | G64: ='Specification Imaging Modalitie'!F9 -> 120000 | H64: ='Specification Imaging Modalitie'!G9 -> 120000 | I64: 120000
A65: Microscope technician ratio | B65: Number of Microscopes maintained by one technician | C65: count | F65: ='Specification Imaging Modalitie'!E10 -> 2 | G65: ='Specification Imaging Modalitie'!F10 -> 5 | H65: ='Specification Imaging Modalitie'!G10 -> 5 | I65: 0.5
A66: Microscope uptime | B66: Fraction of calendar time producing good data, incl Time lost to swaps/alignment beyond uptime | C66: fraction | D66: I assume you can rotate samples in such a way that you keep uptime relatively high still? | F66: ='Specification Imaging Modalitie'!E11 -> 1 | G66: ='Specification Imaging Modalitie'!F11 -> 1 | H66: ='Specification Imaging Modalitie'!G11 -> 1 | I66: 0.99
A67: Reacquisition rate | B67: Expected fraction of volume to re-image | C67: fraction | D67: for simplicity none. Buffer budget at the end accounts for errors | F67: ='Specification Imaging Modalitie'!E12 -> 0 | G67: ='Specification Imaging Modalitie'!F12 -> 0 | H67: ='Specification Imaging Modalitie'!G12 -> 0 | I67: 0
A68: Sample yield | B68: Fraction of samples that pass QC | C68: fraction | D68: for simplicity full. Buffer at the end accounts for errors | F68: ='Specification Imaging Modalitie'!E13 -> 1 | G68: ='Specification Imaging Modalitie'!F13 -> 1 | H68: ='Specification Imaging Modalitie'!G13 -> 1 | I68: 1
A69: Number of microscopes | B69: Scopes operating in parallel | C69: count | D69: calculations | F69: =F14/F58 -> 100 | G69: =G14/G58 -> 100 | H69: =H14/H58 -> 100 | I69: =I14/I58 -> 10
A70: Total Scope operating costs per year | B70: All costs considered | C70: $/scope/year | D70: calculations | F70: =F64/F65+F63 -> 110000 | G70: =G64/G65+G63 -> 39000 | H70: =H64/H65+H63 -> 39000 | I70: =I64/I65+I63 -> 490000
A71: Total microscope costs | B71: All costs over the lifetime of a microscope | C71: $/scope lifetime | D71: calculations | F71: =F58+F70 -> 610000 | G71: =G58+G70 -> 539000 | H71: =H58+H70 -> 539000 | I71: =I58+I70 -> 5490000
A72: Net imaging rate | B72: considering multiple rounds and microscope uptime | C72: Mvox/s | D72: calculations | F72: =F60/(F62/F61)*F66 -> 225 | G72: =G60/(G62/G61)*G66 -> 3300 | H72: =H60/(H62/H61)*H66 -> 11 | I72: =I60/(I62/I61)*I66 -> 247.5
...

Sheet Connectome without proofreading
A1: Connectome with Proofreading
A2: Item | B2: Definition | C2: Units | D2: Sources and Comments | E2: Standardized Variables Proofreading Paradigm | F2: EM | G2: ExM | H2: ExM Molecular Annotation | I2: Wellcome EM Replication
A3: Shared General Specifications
A4: Specifications Organism & Scope
A5: Quality target | B5: Synaptic Resultion, staining only, no antibodies | C5: -
A6: Organism / Region | B6: ='Shared Specifications'!E5 -> Complete Mousebrain | C6: ='Shared Specifications'!C5 -> - | D6: ='Shared Specifications'!D5 | E6: =#REF! -> #REF! | F6: =$E6 -> #REF! | G6: =$E6 -> #REF! | H6: =$E6 -> #REF! | I6: =$E6 -> #REF!
A7: Risk buffer policy first connectome | B7: ='Shared Specifications'!B6 -> Budget and schedule contingency fraction | C7: ='Shared Specifications'!C6 -> fraction | D7: ='Shared Specifications'!D6 -> Standard range of risk buffers | E7: ='Shared Specifications'!E6 -> 0.2 | F7: =$E7 -> 0.2 | G7: =$E7 -> 0.2 | H7: =$E7 -> 0.2 | I7: =$E7 -> 0.2
A8: Risk Buffer for marginal connectomes | B8: ='Shared Specifications'!B7 -> Budget and schedule contingency fraction | C8: ='Shared Specifications'!C7 -> fraction | D8: ='Shared Specifications'!D7 -> Standard range of risk buffers | E8: ='Shared Specifications'!E7 -> 0.05 | F8: =$E8 -> 0.05 | G8: =$E8 -> 0.05 | H8: =$E8 -> 0.05 | I8: =$E8 -> 0.05
A9: Volume (biological) | B9: ='Shared Specifications'!B8 -> Physical brain volume to be mapped | C9: ='Shared Specifications'!C8 -> mm^3 | D9: ='Shared Specifications'!D8 -> Differently sized brains | E9: ='Shared Specifications'!E8 -> 500 | F9: =$E9 -> 500 | G9: =$E9 -> 500 | H9: =$E9 -> 500 | I9: =$E9 -> 500
A10: Number of neurons | B10: ='Shared Specifications'!B9 -> Number of neurons in the given volume | C10: ='Shared Specifications'!C9 -> count | D10: ='Shared Specifications'!D9 -> based on State of Brain Emulation report | E10: ='Shared Specifications'!E9 -> 70000000 | F10: =$E10 -> 70000000 | G10: =$E10 -> 70000000 | H10: =$E10 -> 70000000 | I10: =$E10 -> 70000000
A11: Specifications Counts | B11: ='Shared Specifications'!B10 | C11: ='Shared Specifications'!C10 | D11: ='Shared Specifications'!D10 | E11: ='Shared Specifications'!E10 | F11: =$E11 | G11: =$E11 | H11: =$E11 | I11: =$E11
A12: Years until start | B12: ='Shared Specifications'!B11 -> Years from now when initial purchases are made | C12: ='Shared Specifications'!C11 -> years | D12: ='Shared Specifications'!D11 -> assumptions | E12: ='Shared Specifications'!E11 -> 0 | F12: =$E12 -> 0 | G12: =$E12 -> 0 | H12: =$E12 -> 0 | I12: =$E12 -> 0
A13: Planned Project duration (years) | B13: ='Shared Specifications'!B12 -> Time span for overall project | C13: ='Shared Specifications'!C12 -> years | D13: ='Shared Specifications'!D12 -> assumptions | E13: ='Shared Specifications'!E12 -> 5 | F13: =$E13 -> 5 | G13: =$E13 -> 5 | H13: =$E13 -> 5 | I13: =$E13 -> 5
A14: Dollars available for Microscopes | B14: ='Shared Specifications'!B13 -> Upfront investment in microscopes | C14: ='Shared Specifications'!C13 -> $ | D14: ='Shared Specifications'!D13 -> assumptions | E14: ='Shared Specifications'!E13 -> 50000000 | F14: =$E14 -> 50000000 | G14: =$E14 -> 50000000 | H14: =$E14 -> 50000000 | I14: =$E14 -> 50000000
A15: Max parallel GPUs available | B15: ='Shared Specifications'!B14 -> Number of GPUs dedicated during processing | C15: ='Shared Specifications'!C14 -> count | D15: ='Shared Specifications'!D14 -> assumptions | E15: ='Shared Specifications'!E14 -> 1000 | F15: =$E15 -> 1000 | G15: =$E15 -> 1000 | H15: =$E15 -> 1000 | I15: =$E15 -> 1000
A16: Facility per year | B16: ='Shared Specifications'!B15 -> Cleanroom, isolation, HVAC, racks across whole project lifespan | C16: ='Shared Specifications'!C15 -> $ | D16: ='Shared Specifications'!D15 -> assumptions | E16: ='Shared Specifications'!E15 -> 2000000 | F16: =$E16 -> 2000000 | G16: =$E16 -> 2000000 | H16: =$E16 -> 2000000 | I16: =$E16 -> 2000000
A17: Average Staff salary | B17: ='Shared Specifications'!B16 -> Average salary with all overheads across the project | C17: ='Shared Specifications'!C16 -> $/year | D17: ='Shared Specifications'!D16 -> assumptions | E17: ='Shared Specifications'!E16 -> 150000 | F17: =$E17 -> 150000 | G17: =$E17 -> 150000 | H17: =$E17 -> 150000 | I17: =$E17 -> 150000
A18: Project management staff | B18: ='Shared Specifications'!B17 -> Staff members for management of project oversight | C18: ='Shared Specifications'!C17 -> FTE count | D18: ='Shared Specifications'!D17 -> assumptions | E18: ='Shared Specifications'!E17 -> 10 | F18: =$E18 -> 10 | G18: =$E18 -> 10 | H18: =$E18 -> 10 | I18: =$E18 -> 10
... A49: Segmentation FLOP per voxel | B49: ='Shared Specifications'!B48 -> FP32-equivalent Floating point operations/voxel. | C49: ='Shared Specifications'!C48 -> TFLOP / voxel | D49: ='Shared Specifications'!D48 -> We are assuming 2M FLOP / voxel with LSDs. based on 1/100 of FFN that are 2.42×108 FLOPs/voxel https://www.nature.com/articles/s41592-022-01711-z and https://static-content.springer.com/esm/art%3A10.1038%2Fs41592-018-0049-4/MediaObjects/41592_2018_49_MOESM1_ESM.pdf#page=11 | E49: ='Shared Specifications'!E48 -> 2.4e-06 | F49: =$E49 -> 2.4e-06 | G49: =$E49 -> 2.4e-06 | H49: =$E49 -> 2.4e-06 | I49: =$E49 -> 2.4e-06
A51: Shared Proofreading Specifications
A52: Human proofreading time per neuron | B52: Human proofreading time per neuron | C52: hours | D52: Flywire reports on average 20min per neuron. From personal communication with MICrONS authors we know that bigger mouse neurons can be way more complex and go up to 40h / neuron | E52: =Comparison!F3 -> 0.005 | F52: =$E52 -> 0.005 | G52: =$E52 -> 0.005 | H52: =$E52 -> 0.005 | I52: =$E52 -> 0.005
A53: Hourly rate of proof-reader | B53: Average Compensation for proofreading hour | C53: $/hour | D53: Outsourced salary in non-developped country | E53: =Comparison!F4 -> 50 | F53: =$E53 -> 50 | G53: =$E53 -> 50 | H53: =$E53 -> 50 | I53: =$E53 -> 50
A54: Proofreading hours per day | B54: average hours a proofreader works per day | C54: hours / day | D54: assumption | E54: =Comparison!F5 -> 6 | F54: =$E54 -> 6 | G54: =$E54 -> 6 | H54: =$E54 -> 6 | I54: =$E54 -> 6
A55: Number of proofreaders | B55: Number of people proofreading. | C55: count | D55: backchaining from Wellcome estimate and Targeting 5years with people working 6h / day for 210 days per year for a mouse | E55: =Comparison!F6 -> 1000 | F55: =$E55 -> 1000 | G55: =$E55 -> 1000 | H55: =$E55 -> 1000 | I55: =$E55 -> 1000
A57: Unique Specifications Microscope | F57: ='Specification Imaging Modalitie'!E2 -> https://www.nature.com/articles/s41467-024-50846-4
A58: Microscope capital cost | B58: Acquisition price per scope | C58: $/scope | F58: ='Specification Imaging Modalitie'!E3 -> 500000 | G58: ='Specification Imaging Modalitie'!F3 -> 500000 | H58: ='Specification Imaging Modalitie'!G3 -> 500000 | I58: ='Specification Imaging Modalitie'!H3 -> 5000000
A59: Microscope depreciation horizon | B59: Straight-line depreciation years | C59: yr | F59: ='Specification Imaging Modalitie'!E4 -> 10 | G59: ='Specification Imaging Modalitie'!F4 -> 5 | H59: ='Specification Imaging Modalitie'!G4 -> 5 | I59: ='Specification Imaging Modalitie'!H4 -> 10
A60: Sustained Imaging Rate | B60: Sustained Imaging rate at given resolution per Microscope, i.e. voxels/second/scope | C60: Mvox/s | D60: This seems to be quite similar to EMs out there, both in terms of bursts going into the GHz and continuous around 100s of MHz | F60: ='Specification Imaging Modalitie'!E5 -> 225 | G60: ='Specification Imaging Modalitie'!F5 -> 1100 | H60: ='Specification Imaging Modalitie'!G5 -> 1100 | I60: ='Specification Imaging Modalitie'!H5 -> 250
A61: Parallel Channels per round | B61: simultaneous channel readouts (not sequential during one round) | D61: Just staining, no antibodies | F61: ='Specification Imaging Modalitie'!E6 -> 1 | G61: ='Specification Imaging Modalitie'!F6 -> 3 | H61: ='Specification Imaging Modalitie'!G6 -> 8 | I61: ='Specification Imaging Modalitie'!H6 -> 1
A62: Total Channels | B62: Imaging channels per voxel | C62: count | D62: Just staining, no antibodies | F62: ='Specification Imaging Modalitie'!E7 -> 1 | G62: ='Specification Imaging Modalitie'!F7 -> 1 | H62: ='Specification Imaging Modalitie'!G7 -> 800 | I62: ='Specification Imaging Modalitie'!H7 -> 1
A63: Scope annual service | B63: Electricity, licenses, Maintenance or spares | C63: $/scope/year | F63: ='Specification Imaging Modalitie'!E8 -> 50000 | G63: ='Specification Imaging Modalitie'!F8 -> 15000 | H63: ='Specification Imaging Modalitie'!G8 -> 15000 | I63: ='Specification Imaging Modalitie'!H8 -> 250000
A64: Salary Microscope technician | B64: Total Salary, incl benefits etc. for microscopist (incl. wetlab work) | C64: $/year | F64: ='Specification Imaging Modalitie'!E9 -> 120000 | G64: ='Specification Imaging Modalitie'!F9 -> 120000 | H64: ='Specification Imaging Modalitie'!G9 -> 120000 | I64: ='Specification Imaging Modalitie'!H9 -> 120000
A65: Microscope technician ratio | B65: Number of Microscopes maintained by one technician | C65: count | F65: ='Specification Imaging Modalitie'!E10 -> 2 | G65: ='Specification Imaging Modalitie'!F10 -> 5 | H65: ='Specification Imaging Modalitie'!G10 -> 5 | I65: ='Specification Imaging Modalitie'!H10 -> 0.5
A66: Microscope uptime | B66: Fraction of calendar time producing good data, incl Time lost to swaps/alignment beyond uptime | C66: fraction | D66: I assume you can rotate samples in such a way that you keep uptime relatively high still? | F66: ='Specification Imaging Modalitie'!E11 -> 1 | G66: ='Specification Imaging Modalitie'!F11 -> 1 | H66: ='Specification Imaging Modalitie'!G11 -> 1 | I66: ='Specification Imaging Modalitie'!H11 -> 1
A67: Reacquisition rate | B67: Expected fraction of volume to re-image | C67: fraction | D67: for simplicity none. Buffer budget at the end accounts for errors | F67: ='Specification Imaging Modalitie'!E12 -> 0 | G67: ='Specification Imaging Modalitie'!F12 -> 0 | H67: ='Specification Imaging Modalitie'!G12 -> 0 | I67: ='Specification Imaging Modalitie'!H12 -> 0
A68: Sample yield | B68: Fraction of samples that pass QC | C68: fraction | D68: for simplicity full. Buffer at the end accounts for errors | F68: ='Specification Imaging Modalitie'!E13 -> 1 | G68: ='Specification Imaging Modalitie'!F13 -> 1 | H68: ='Specification Imaging Modalitie'!G13 -> 1 | I68: ='Specification Imaging Modalitie'!H13 -> 1
A69: Number of microscopes | B69: Scopes operating in parallel | C69: count | D69: calculations | F69: =F14/F58 -> 100 | G69: =G14/G58 -> 100 | H69: =H14/H58 -> 100 | I69: =I14/I58 -> 10
A70: Total Scope operating costs per year | B70: All costs considered | C70: $/scope/year | D70: calculations | F70: =F64/F65+F63 -> 110000 | G70: =G64/G65+G63 -> 39000 | H70: =H64/H65+H63 -> 39000 | I70: =I64/I65+I63 -> 490000
A71: Total microscope costs | B71: All costs over the lifetime of a microscope | C71: $/scope lifetime | D71: calculations | F71: =F58+F70 -> 610000 | G71: =G58+G70 -> 539000 | H71: =H58+H70 -> 539000 | I71: =I58+I70 -> 5490000
A72: Net imaging rate | B72: considering multiple rounds and microscope uptime | C72: Mvox/s | D72: calculations | F72: =F60/(F62/F61)*F66 -> 225 | G72: =G60/(G62/G61)*G66 -> 3300 | H72: =H60/(H62/H61)*H66 -> 11 | I72: =I60/(I62/I61)*I66 -> 250
...
